<!-- A four-legged model with vertical legs and nearly even length thigh and calf links. Rotation of hips and knees aligns. Hips are given a full 180 degrees of movement. Legs are positioned in the four corners. -->
<?xml version='1.0'?>
<sdf version='1.4'>
  <model name="Even">
    <static>false</static>
    <self_collide>1</self_collide>
      <link name='body'>
        <pose>0 0 1.31 0 0 0</pose>
        <inertial>
          <mass>20</mass>
        </inertial>
        <collision name='collision'>
          <pose frame=''>0 0 0 0 0 0</pose>
          <geometry>
            <box>
              <size>4 1 .5</size>
            </box>
          </geometry>
        </collision>
          <visual name='visual'>
          <pose>0 0 0 0 0 0</pose>
          <geometry>
            <box>
              <size>4 1 .5</size>
            </box>
          </geometry>
        </visual>
      </link>

      
      <!-- front left leg -->
      <include>
        <uri>model://EvenLeg</uri>
        <pose> 1.9 .45 0 0 0 0</pose>
        <name>fl_leg</name>
      </include>
      <joint name="body_to_fl_leg" type="revolute">
        <child>fl_leg::r_thigh_lift</child>
        <parent>body</parent>
        <pose frame=''>0 0 0.3 0 0 0</pose>
        <axis>
          <xyz>0 1 0</xyz>
          <limit>
          <lower>-1.57</lower>
          <upper>1.57</upper>
        </limit>
        </axis>
      </joint>

      <!-- front right leg -->
      <include>
        <uri>model://EvenLeg</uri>
        <pose> 1.9 -.45 0 0 0 0</pose>
        <name>fr_leg</name>
      </include>
      <joint name="body_to_fr_leg" type="revolute">
        <child>fr_leg::r_thigh_lift</child>
        <parent>body</parent>
        <pose frame=''>0 0 0.3 0 0 0</pose>
        <axis>
          <xyz>0 1 0</xyz>
          <limit>
          <lower>-1.57</lower>
          <upper>1.57</upper>
        </limit>
        </axis>
      </joint>


     
      <!-- rear left leg -->
      <include>
        <uri>model://EvenLeg</uri>
        <pose>-1.9 0.45 0 0 0 0</pose>
        <name>rl_leg</name>
      </include>
      <joint name="body_to_rl_leg" type="revolute">
        <child>rl_leg::r_thigh_lift</child>
        <parent>body</parent>
        <pose frame=''>0 0 0.3 0 0 0</pose>
        <axis>
          <xyz>0 1 0</xyz>
          <limit>
          <lower>-1.57</lower>
          <upper>1.57</upper>
        </limit>
        </axis>
      </joint>

      <!-- rear right leg -->
      <include>
        <uri>model://EvenLeg</uri>
        <pose>-1.9 -0.45 0 0 0 0</pose>
        <name>rr_leg</name>
      </include>
      <joint name="body_to_rr_leg" type="revolute">
        <child>rr_leg::r_thigh_lift</child>
        <parent>body</parent>
        <pose frame=''>0 0 0.3 0 0 0</pose>
        <axis>
          <xyz>0 1 0</xyz>
          <limit>
          <lower>-1.57</lower>
          <upper>1.57</upper>
        </limit>
        </axis>
      </joint>
      <self_collide>1</self_collide>
    </model>
</sdf>
