<!-- This Model is designed to move "like a crab". Knee and hip joints rotate in the same direction.  -->
<?xml version='1.0'?>
<sdf version='1.4'>
  <model name="Crab">
    <static>false</static>
    <self_collide>1</self_collide>
    <!-- Defines the body Position, mass, collision and visuals. All masses are proportional to volume (i.e models have uniform density). The body model is a rectangular prism.-->
      <link name='body'>
        <pose>0 0 .5 0 0 0</pose>
        <inertial>
          <mass>20</mass>
        </inertial>
        <collision name='collision'>
          <pose frame=''>0 0 0 0 0 0</pose>
          <geometry>
            <box>
              <size>4 1 .5</size>
            </box>
          </geometry>
        </collision>
          <visual name='visual'>
          <pose>0 0 0 0 0 0</pose>
          <geometry>
            <box>
              <size>4 1 .5</size>
            </box>
          </geometry>
        </visual>
      </link>

      <!-- Six legs are positioned on the corner and middle of the body, rotated 90 degrees from vertical. Legs rotate around the x -axis ("up and down" relative to the body. The legs can rotate downward so as to be completely vertical but can only go 30 degrees above horizontal.-->
      <!-- front left leg -->
      <include>
        <uri>model://CrabLeg</uri>
        <pose> 1.9 1 0 0 0 -1.57</pose>
        <name>fl_leg</name>
      </include>
      <joint name="body_to_fl_leg" type="revolute">
        <child>fl_leg::r_thigh_lift</child>
        <parent>body</parent>
        <pose frame=''>0 0 0.3 0 0 0</pose>
        <axis>
          <xyz>1 0 0</xyz>
          <limit>
          <lower>-0.523</lower>
          <upper>1.57</upper>
        </limit>
        </axis>
      </joint>

      <!-- front right leg -->
      <include>
        <uri>model://CrabLeg</uri>
        <pose> 1.9 -1 0 0 0 1.57</pose>
        <name>fr_leg</name>
      </include>
      <joint name="body_to_fr_leg" type="revolute">
        <child>fr_leg::r_thigh_lift</child>
        <parent>body</parent>
        <pose frame=''>0 0 0.3 0 0 0</pose>
        <axis>
          <xyz> 1 0 0</xyz>
          <limit>
          <lower>-0.523</lower>
          <upper>1.57</upper>
        </limit>
        </axis>
      </joint>

        <!-- middle left leg -->
      <include>
        <uri>model://CrabLeg</uri>
        <pose>0 1 0 0 0 -1.57</pose>
        <name>ml_leg</name>
      </include>
      <joint name="body_to_ml_leg" type="revolute">
        <child>ml_leg::r_thigh_lift</child>
        <parent>body</parent>
        <pose frame=''>0 0 0.3 0 0 0</pose>
        <axis>
          <xyz>1 0 0</xyz>
          <limit>
          <lower>-0.523</lower>
          <upper>1.57</upper>
        </limit>
        </axis>
      </joint>

      <!-- middle right leg -->
      <include>
        <uri>model://CrabLeg</uri>
        <pose>0 -1 0 0 0 1.57</pose>
        <name>mr_leg</name>
      </include>
      <joint name="body_to_mr_leg" type="revolute">
        <child>mr_leg::r_thigh_lift</child>
        <parent>body</parent>
        <pose frame=''>0 0 0.3 0 0 0</pose>
        <axis>
          <xyz>1 0 0</xyz>
          <limit>
          <lower>-0.523</lower>
          <upper>1.57</upper>
        </limit>
        </axis>
      </joint>
      
     
      <!-- rear left leg -->
      <include>
        <uri>model://CrabLeg</uri>
        <pose>-1.9 1 0 0 0 -1.57</pose>
        <name>rl_leg</name>
      </include>
      <joint name="body_to_rl_leg" type="revolute">
        <child>rl_leg::r_thigh_lift</child>
        <parent>body</parent>
        <pose frame=''>0 0 0.3 0 0 0</pose>
        <axis>
          <xyz>1 0 0</xyz>
          <limit>
          <lower>-0.523</lower>
          <upper>1.57</upper>
        </limit>
        </axis>
      </joint>

      <!-- rear right leg -->
      <include>
        <uri>model://CrabLeg</uri>
        <pose>-1.9 -1 0 0 0 1.57</pose>
        <name>rr_leg</name>
      </include>
      <joint name="body_to_rr_leg" type="revolute">
        <child>rr_leg::r_thigh_lift</child>
        <parent>body</parent>
        <pose frame=''>0 0 0.3 0 0 0</pose>
        <axis>
          <xyz>1 0 0</xyz>
          <limit>
          <lower>-0.523</lower>
          <upper>1.57</upper>
        </limit>
        </axis>
      </joint>

      <self_collide>1</self_collide>

    </model>
</sdf>
